04/Nov/2022 11:09:02 [Thread-2:24256] [django.request:222] [ERROR]- Internal Server Error: /userinfo
Traceback (most recent call last):
  File "C:\Users\silk\Desktop\work_space\shopping_demo\venv\lib\site-packages\django\core\handlers\exception.py", line 34, in inner
    response = get_response(request)
  File "C:\Users\silk\Desktop\work_space\shopping_demo\venv\lib\site-packages\django\core\handlers\base.py", line 126, in _get_response
    response = self.process_exception_by_middleware(e, request)
  File "C:\Users\silk\Desktop\work_space\shopping_demo\venv\lib\site-packages\django\core\handlers\base.py", line 124, in _get_response
    response = wrapped_callback(request, *callback_args, **callback_kwargs)
  File "C:\Users\silk\Desktop\work_space\shopping_demo\apps\users\views.py", line 8, in get_userinfo
    result = render(request, 'userinfo.html', context={
  File "C:\Users\silk\Desktop\work_space\shopping_demo\venv\lib\site-packages\django\shortcuts.py", line 36, in render
    content = loader.render_to_string(template_name, context, request, using=using)
  File "C:\Users\silk\Desktop\work_space\shopping_demo\venv\lib\site-packages\django\template\loader.py", line 61, in render_to_string
    template = get_template(template_name, using=using)
  File "C:\Users\silk\Desktop\work_space\shopping_demo\venv\lib\site-packages\django\template\loader.py", line 19, in get_template
    raise TemplateDoesNotExist(template_name, chain=chain)
django.template.exceptions.TemplateDoesNotExist: userinfo.html
04/Nov/2022 11:09:02 [Thread-4:13668] [django.request:222] [ERROR]- Internal Server Error: /userinfo
Traceback (most recent call last):
  File "C:\Users\silk\Desktop\work_space\shopping_demo\venv\lib\site-packages\django\core\handlers\exception.py", line 34, in inner
    response = get_response(request)
  File "C:\Users\silk\Desktop\work_space\shopping_demo\venv\lib\site-packages\django\core\handlers\base.py", line 126, in _get_response
    response = self.process_exception_by_middleware(e, request)
  File "C:\Users\silk\Desktop\work_space\shopping_demo\venv\lib\site-packages\django\core\handlers\base.py", line 124, in _get_response
    response = wrapped_callback(request, *callback_args, **callback_kwargs)
  File "C:\Users\silk\Desktop\work_space\shopping_demo\apps\users\views.py", line 8, in get_userinfo
    result = render(request, 'userinfo.html', context={
  File "C:\Users\silk\Desktop\work_space\shopping_demo\venv\lib\site-packages\django\shortcuts.py", line 36, in render
    content = loader.render_to_string(template_name, context, request, using=using)
  File "C:\Users\silk\Desktop\work_space\shopping_demo\venv\lib\site-packages\django\template\loader.py", line 61, in render_to_string
    template = get_template(template_name, using=using)
  File "C:\Users\silk\Desktop\work_space\shopping_demo\venv\lib\site-packages\django\template\loader.py", line 19, in get_template
    raise TemplateDoesNotExist(template_name, chain=chain)
django.template.exceptions.TemplateDoesNotExist: userinfo.html
04/Nov/2022 11:09:05 [Thread-5:44580] [django.request:222] [ERROR]- Internal Server Error: /userinfo
Traceback (most recent call last):
  File "C:\Users\silk\Desktop\work_space\shopping_demo\venv\lib\site-packages\django\core\handlers\exception.py", line 34, in inner
    response = get_response(request)
  File "C:\Users\silk\Desktop\work_space\shopping_demo\venv\lib\site-packages\django\core\handlers\base.py", line 126, in _get_response
    response = self.process_exception_by_middleware(e, request)
  File "C:\Users\silk\Desktop\work_space\shopping_demo\venv\lib\site-packages\django\core\handlers\base.py", line 124, in _get_response
    response = wrapped_callback(request, *callback_args, **callback_kwargs)
  File "C:\Users\silk\Desktop\work_space\shopping_demo\apps\users\views.py", line 8, in get_userinfo
    result = render(request, 'userinfo.html', context={
  File "C:\Users\silk\Desktop\work_space\shopping_demo\venv\lib\site-packages\django\shortcuts.py", line 36, in render
    content = loader.render_to_string(template_name, context, request, using=using)
  File "C:\Users\silk\Desktop\work_space\shopping_demo\venv\lib\site-packages\django\template\loader.py", line 61, in render_to_string
    template = get_template(template_name, using=using)
  File "C:\Users\silk\Desktop\work_space\shopping_demo\venv\lib\site-packages\django\template\loader.py", line 19, in get_template
    raise TemplateDoesNotExist(template_name, chain=chain)
django.template.exceptions.TemplateDoesNotExist: userinfo.html
04/Nov/2022 11:09:09 [Thread-5:44580] [django.request:222] [ERROR]- Internal Server Error: /userinfo
Traceback (most recent call last):
  File "C:\Users\silk\Desktop\work_space\shopping_demo\venv\lib\site-packages\django\core\handlers\exception.py", line 34, in inner
    response = get_response(request)
  File "C:\Users\silk\Desktop\work_space\shopping_demo\venv\lib\site-packages\django\core\handlers\base.py", line 126, in _get_response
    response = self.process_exception_by_middleware(e, request)
  File "C:\Users\silk\Desktop\work_space\shopping_demo\venv\lib\site-packages\django\core\handlers\base.py", line 124, in _get_response
    response = wrapped_callback(request, *callback_args, **callback_kwargs)
  File "C:\Users\silk\Desktop\work_space\shopping_demo\apps\users\views.py", line 8, in get_userinfo
    result = render(request, 'userinfo.html', context={
  File "C:\Users\silk\Desktop\work_space\shopping_demo\venv\lib\site-packages\django\shortcuts.py", line 36, in render
    content = loader.render_to_string(template_name, context, request, using=using)
  File "C:\Users\silk\Desktop\work_space\shopping_demo\venv\lib\site-packages\django\template\loader.py", line 61, in render_to_string
    template = get_template(template_name, using=using)
  File "C:\Users\silk\Desktop\work_space\shopping_demo\venv\lib\site-packages\django\template\loader.py", line 19, in get_template
    raise TemplateDoesNotExist(template_name, chain=chain)
django.template.exceptions.TemplateDoesNotExist: userinfo.html
04/Nov/2022 11:09:09 [Thread-5:44580] [django.request:222] [ERROR]- Internal Server Error: /userinfo
Traceback (most recent call last):
  File "C:\Users\silk\Desktop\work_space\shopping_demo\venv\lib\site-packages\django\core\handlers\exception.py", line 34, in inner
    response = get_response(request)
  File "C:\Users\silk\Desktop\work_space\shopping_demo\venv\lib\site-packages\django\core\handlers\base.py", line 126, in _get_response
    response = self.process_exception_by_middleware(e, request)
  File "C:\Users\silk\Desktop\work_space\shopping_demo\venv\lib\site-packages\django\core\handlers\base.py", line 124, in _get_response
    response = wrapped_callback(request, *callback_args, **callback_kwargs)
  File "C:\Users\silk\Desktop\work_space\shopping_demo\apps\users\views.py", line 8, in get_userinfo
    result = render(request, 'userinfo.html', context={
  File "C:\Users\silk\Desktop\work_space\shopping_demo\venv\lib\site-packages\django\shortcuts.py", line 36, in render
    content = loader.render_to_string(template_name, context, request, using=using)
  File "C:\Users\silk\Desktop\work_space\shopping_demo\venv\lib\site-packages\django\template\loader.py", line 61, in render_to_string
    template = get_template(template_name, using=using)
  File "C:\Users\silk\Desktop\work_space\shopping_demo\venv\lib\site-packages\django\template\loader.py", line 19, in get_template
    raise TemplateDoesNotExist(template_name, chain=chain)
django.template.exceptions.TemplateDoesNotExist: userinfo.html
